Workbook

Sheet Planilha de Cadastro - Previsão
A1: Lote | B1: Item | C1: Quantidade | D1: Valor da Compra (UN.) | E1: Valor da Venda (UN.) | F1: % de Lucro | G1: % Comissão | H1: $ Comissão | I1: Marca/Modelo | J1: Link | K1: Responsável Pelo Orçamento | L1: Valor da Venda Real | M1: Lucro Real | N1: Vencedor | O1: Compra Preen | P1: Imposto
F2: =IF(B2>0,(((E2*C2)-(D2*C2)-(P2*C2))/(E2*C2)),"") | G2: =IF(F2="","",IF(F2<0.2,0.05,IF(F2<0.25,0.1,IF(F2<0.3,0.15,IF(F2<0.35,0.2,IF(F2<0.45,0.25,IF(F2<0.5,0.3,IF(F2<0.6,0.35,0.4)))))))) | H2: =IFERROR(((E2*C2)-(D2*C2)-(E2*C2*4%))*G2,"") | L2: =IFERROR(VLOOKUP(A2,'Acompanhamento da Licitação'!$F$2:$N$1000,6,FALSE()),"") | M2: =IFERROR(VLOOKUP(A2,'Acompanhamento da Licitação'!$F$2:$N$1000,7,FALSE()),"") | N2: =IFERROR(VLOOKUP(A2,'Acompanhamento da Licitação'!$F$2:$N$1000,9,FALSE()),"") | O2: =IF(AND(D2>0,F2>0.25),"Sim","Não") -> Não | P2: =4%*E2 -> 0 | R2: Alef Freire
F3: =IF(B3>0,(((E3*C3)-(D3*C3)-(P3*C3))/(E3*C3)),"") | G3: =IF(F3="","",IF(F3<0.2,0.05,IF(F3<0.25,0.1,IF(F3<0.3,0.15,IF(F3<0.35,0.2,IF(F3<0.45,0.25,IF(F3<0.5,0.3,IF(F3<0.6,0.35,0.4)))))))) | H3: =IFERROR(((E3*C3)-(D3*C3)-(E3*C3*4%))*G3,"") | L3: =IFERROR(VLOOKUP(A3,'Acompanhamento da Licitação'!$F$2:$N$1000,6,FALSE()),"") | M3: =IFERROR(VLOOKUP(A3,'Acompanhamento da Licitação'!$F$2:$N$1000,7,FALSE()),"") | N3: =IFERROR(VLOOKUP(A3,'Acompanhamento da Licitação'!$F$2:$N$1000,9,FALSE()),"") | O3: =IF(AND(D3>0,F3>0.25),"Sim","Não") -> Não | P3: =4%*E3 -> 0 | R3: Anna Carolina
F4: =IF(B4>0,(((E4*C4)-(D4*C4)-(P4*C4))/(E4*C4)),"") | G4: =IF(F4="","",IF(F4<0.2,0.05,IF(F4<0.25,0.1,IF(F4<0.3,0.15,IF(F4<0.35,0.2,IF(F4<0.45,0.25,IF(F4<0.5,0.3,IF(F4<0.6,0.35,0.4)))))))) | H4: =IFERROR(((E4*C4)-(D4*C4)-(E4*C4*4%))*G4,"") | L4: =IFERROR(VLOOKUP(A4,'Acompanhamento da Licitação'!$F$2:$N$1000,6,FALSE()),"") | M4: =IFERROR(VLOOKUP(A4,'Acompanhamento da Licitação'!$F$2:$N$1000,7,FALSE()),"") | N4: =IFERROR(VLOOKUP(A4,'Acompanhamento da Licitação'!$F$2:$N$1000,9,FALSE()),"") | O4: =IF(AND(D4>0,F4>0.25),"Sim","Não") -> Não | P4: =4%*E4 -> 0 | R4: Ariane Vieira
F5: =IF(B5>0,(((E5*C5)-(D5*C5)-(P5*C5))/(E5*C5)),"") | G5: =IF(F5="","",IF(F5<0.2,0.05,IF(F5<0.25,0.1,IF(F5<0.3,0.15,IF(F5<0.35,0.2,IF(F5<0.45,0.25,IF(F5<0.5,0.3,IF(F5<0.6,0.35,0.4)))))))) | H5: =IFERROR(((E5*C5)-(D5*C5)-(E5*C5*4%))*G5,"") | L5: =IFERROR(VLOOKUP(A5,'Acompanhamento da Licitação'!$F$2:$N$1000,6,FALSE()),"") | M5: =IFERROR(VLOOKUP(A5,'Acompanhamento da Licitação'!$F$2:$N$1000,7,FALSE()),"") | N5: =IFERROR(VLOOKUP(A5,'Acompanhamento da Licitação'!$F$2:$N$1000,9,FALSE()),"") | O5: =IF(AND(D5>0,F5>0.25),"Sim","Não") -> Não | P5: =4%*E5 -> 0 | R5: Barbara Jordão
F6: =IF(B6>0,(((E6*C6)-(D6*C6)-(P6*C6))/(E6*C6)),"") | G6: =IF(F6="","",IF(F6<0.2,0.05,IF(F6<0.25,0.1,IF(F6<0.3,0.15,IF(F6<0.35,0.2,IF(F6<0.45,0.25,IF(F6<0.5,0.3,IF(F6<0.6,0.35,0.4)))))))) | H6: =IFERROR(((E6*C6)-(D6*C6)-(E6*C6*4%))*G6,"") | L6: =IFERROR(VLOOKUP(A6,'Acompanhamento da Licitação'!$F$2:$N$1000,6,FALSE()),"") | M6: =IFERROR(VLOOKUP(A6,'Acompanhamento da Licitação'!$F$2:$N$1000,7,FALSE()),"") | N6: =IFERROR(VLOOKUP(A6,'Acompanhamento da Licitação'!$F$2:$N$1000,9,FALSE()),"") | O6: =IF(AND(D6>0,F6>0.25),"Sim","Não") -> Não | P6: =4%*E6 -> 0 | R6: Damiana Alvelino
F7: =IF(B7>0,(((E7*C7)-(D7*C7)-(P7*C7))/(E7*C7)),"") | G7: =IF(F7="","",IF(F7<0.2,0.05,IF(F7<0.25,0.1,IF(F7<0.3,0.15,IF(F7<0.35,0.2,IF(F7<0.45,0.25,IF(F7<0.5,0.3,IF(F7<0.6,0.35,0.4)))))))) | H7: =IFERROR(((E7*C7)-(D7*C7)-(E7*C7*4%))*G7,"") | L7: =IFERROR(VLOOKUP(A7,'Acompanhamento da Licitação'!$F$2:$N$1000,6,FALSE()),"") | M7: =IFERROR(VLOOKUP(A7,'Acompanhamento da Licitação'!$F$2:$N$1000,7,FALSE()),"") | N7: =IFERROR(VLOOKUP(A7,'Acompanhamento da Licitação'!$F$2:$N$1000,9,FALSE()),"") | O7: =IF(AND(D7>0,F7>0.25),"Sim","Não") -> Não | P7: =4%*E7 -> 0 | R7: Equipe Mabus
F8: =IF(B8>0,(((E8*C8)-(D8*C8)-(P8*C8))/(E8*C8)),"") | G8: =IF(F8="","",IF(F8<0.2,0.05,IF(F8<0.25,0.1,IF(F8<0.3,0.15,IF(F8<0.35,0.2,IF(F8<0.45,0.25,IF(F8<0.5,0.3,IF(F8<0.6,0.35,0.4)))))))) | H8: =IFERROR(((E8*C8)-(D8*C8)-(E8*C8*4%))*G8,"") | L8: =IFERROR(VLOOKUP(A8,'Acompanhamento da Licitação'!$F$2:$N$1000,6,FALSE()),"") | M8: =IFERROR(VLOOKUP(A8,'Acompanhamento da Licitação'!$F$2:$N$1000,7,FALSE()),"") | N8: =IFERROR(VLOOKUP(A8,'Acompanhamento da Licitação'!$F$2:$N$1000,9,FALSE()),"") | O8: =IF(AND(D8>0,F8>0.25),"Sim","Não") -> Não | P8: =4%*E8 -> 0 | R8: Gabrielly Freitas
F9: =IF(B9>0,(((E9*C9)-(D9*C9)-(P9*C9))/(E9*C9)),"") | G9: =IF(F9="","",IF(F9<0.2,0.05,IF(F9<0.25,0.1,IF(F9<0.3,0.15,IF(F9<0.35,0.2,IF(F9<0.45,0.25,IF(F9<0.5,0.3,IF(F9<0.6,0.35,0.4)))))))) | H9: =IFERROR(((E9*C9)-(D9*C9)-(E9*C9*4%))*G9,"") | L9: =IFERROR(VLOOKUP(A9,'Acompanhamento da Licitação'!$F$2:$N$1000,6,FALSE()),"") | M9: =IFERROR(VLOOKUP(A9,'Acompanhamento da Licitação'!$F$2:$N$1000,7,FALSE()),"") | N9: =IFERROR(VLOOKUP(A9,'Acompanhamento da Licitação'!$F$2:$N$1000,9,FALSE()),"") | O9: =IF(AND(D9>0,F9>0.25),"Sim","Não") -> Não | P9: =4%*E9 -> 0 | R9: Geovanna Candido
F10: =IF(B10>0,(((E10*C10)-(D10*C10)-(P10*C10))/(E10*C10)),"") | G10: =IF(F10="","",IF(F10<0.2,0.05,IF(F10<0.25,0.1,IF(F10<0.3,0.15,IF(F10<0.35,0.2,IF(F10<0.45,0.25,IF(F10<0.5,0.3,IF(F10<0.6,0.35,0.4)))))))) | H10: =IFERROR(((E10*C10)-(D10*C10)-(E10*C10*4%))*G10,"") | L10: =IFERROR(VLOOKUP(A10,'Acompanhamento da Licitação'!$F$2:$N$1000,6,FALSE()),"") | M10: =IFERROR(VLOOKUP(A10,'Acompanhamento da Licitação'!$F$2:$N$1000,7,FALSE()),"") | N10: =IFERROR(VLOOKUP(A10,'Acompanhamento da Licitação'!$F$2:$N$1000,9,FALSE()),"") | O10: =IF(AND(D10>0,F10>0.25),"Sim","Não") -> Não | P10: =4%*E10 -> 0 | R10: Guilherme Cândido
F11: =IF(B11>0,(((E11*C11)-(D11*C11)-(P11*C11))/(E11*C11)),"") | G11: =IF(F11="","",IF(F11<0.2,0.05,IF(F11<0.25,0.1,IF(F11<0.3,0.15,IF(F11<0.35,0.2,IF(F11<0.45,0.25,IF(F11<0.5,0.3,IF(F11<0.6,0.35,0.4)))))))) | H11: =IFERROR(((E11*C11)-(D11*C11)-(E11*C11*4%))*G11,"") | L11: =IFERROR(VLOOKUP(A11,'Acompanhamento da Licitação'!$F$2:$N$1000,6,FALSE()),"") | M11: =IFERROR(VLOOKUP(A11,'Acompanhamento da Licitação'!$F$2:$N$1000,7,FALSE()),"") | N11: =IFERROR(VLOOKUP(A11,'Acompanhamento da Licitação'!$F$2:$N$1000,9,FALSE()),"") | O11: =IF(AND(D11>0,F11>0.25),"Sim","Não") -> Não | P11: =4%*E11 -> 0 | R11: Heverton Moreira
F12: =IF(B12>0,(((E12*C12)-(D12*C12)-(P12*C12))/(E12*C12)),"") | G12: =IF(F12="","",IF(F12<0.2,0.05,IF(F12<0.25,0.1,IF(F12<0.3,0.15,IF(F12<0.35,0.2,IF(F12<0.45,0.25,IF(F12<0.5,0.3,IF(F12<0.6,0.35,0.4)))))))) | H12: =IFERROR(((E12*C12)-(D12*C12)-(E12*C12*4%))*G12,"") | L12: =IFERROR(VLOOKUP(A12,'Acompanhamento da Licitação'!$F$2:$N$1000,6,FALSE()),"") | M12: =IFERROR(VLOOKUP(A12,'Acompanhamento da Licitação'!$F$2:$N$1000,7,FALSE()),"") | N12: =IFERROR(VLOOKUP(A12,'Acompanhamento da Licitação'!$F$2:$N$1000,9,FALSE()),"") | O12: =IF(AND(D12>0,F12>0.25),"Sim","Não") -> Não | P12: =4%*E12 -> 0 | R12: Isabela Gontijo
F13: =IF(B13>0,(((E13*C13)-(D13*C13)-(P13*C13))/(E13*C13)),"") | G13: =IF(F13="","",IF(F13<0.2,0.05,IF(F13<0.25,0.1,IF(F13<0.3,0.15,IF(F13<0.35,0.2,IF(F13<0.45,0.25,IF(F13<0.5,0.3,IF(F13<0.6,0.35,0.4)))))))) | H13: =IFERROR(((E13*C13)-(D13*C13)-(E13*C13*4%))*G13,"") | L13: =IFERROR(VLOOKUP(A13,'Acompanhamento da Licitação'!$F$2:$N$1000,6,FALSE()),"") | M13: =IFERROR(VLOOKUP(A13,'Acompanhamento da Licitação'!$F$2:$N$1000,7,FALSE()),"") | N13: =IFERROR(VLOOKUP(A13,'Acompanhamento da Licitação'!$F$2:$N$1000,9,FALSE()),"") | O13: =IF(AND(D13>0,F13>0.25),"Sim","Não") -> Não | P13: =4%*E13 -> 0 | R13: João Vitor Ferreira
... F21: =IF(B21>0,(((E21*C21)-(D21*C21)-(P21*C21))/(E21*C21)),"") | G21: =IF(F21="","",IF(F21<0.2,0.05,IF(F21<0.25,0.1,IF(F21<0.3,0.15,IF(F21<0.35,0.2,IF(F21<0.45,0.25,IF(F21<0.5,0.3,IF(F21<0.6,0.35,0.4)))))))) | H21: =IFERROR(((E21*C21)-(D21*C21)-(E21*C21*4%))*G21,"") | L21: =IFERROR(VLOOKUP(A21,'Acompanhamento da Licitação'!$F$2:$N$1000,6,FALSE()),"") | M21: =IFERROR(VLOOKUP(A21,'Acompanhamento da Licitação'!$F$2:$N$1000,7,FALSE()),"") | N21: =IFERROR(VLOOKUP(A21,'Acompanhamento da Licitação'!$F$2:$N$1000,9,FALSE()),"") | O21: =IF(AND(D21>0,F21>0.25),"Sim","Não") -> Não | P21: =4%*E21 -> 0 | R21: Thiago Alves
F22: =IF(B22>0,(((E22*C22)-(D22*C22)-(P22*C22))/(E22*C22)),"") | G22: =IF(F22="","",IF(F22<0.2,0.05,IF(F22<0.25,0.1,IF(F22<0.3,0.15,IF(F22<0.35,0.2,IF(F22<0.45,0.25,IF(F22<0.5,0.3,IF(F22<0.6,0.35,0.4)))))))) | H22: =IFERROR(((E22*C22)-(D22*C22)-(E22*C22*4%))*G22,"") | L22: =IFERROR(VLOOKUP(A22,'Acompanhamento da Licitação'!$F$2:$N$1000,6,FALSE()),"") | M22: =IFERROR(VLOOKUP(A22,'Acompanhamento da Licitação'!$F$2:$N$1000,7,FALSE()),"") | N22: =IFERROR(VLOOKUP(A22,'Acompanhamento da Licitação'!$F$2:$N$1000,9,FALSE()),"") | O22: =IF(AND(D22>0,F22>0.25),"Sim","Não") -> Não | P22: =4%*E22 -> 0
F23: =IF(B23>0,(((E23*C23)-(D23*C23)-(P23*C23))/(E23*C23)),"") | G23: =IF(F23="","",IF(F23<0.2,0.05,IF(F23<0.25,0.1,IF(F23<0.3,0.15,IF(F23<0.35,0.2,IF(F23<0.45,0.25,IF(F23<0.5,0.3,IF(F23<0.6,0.35,0.4)))))))) | H23: =IFERROR(((E23*C23)-(D23*C23)-(E23*C23*4%))*G23,"") | L23: =IFERROR(VLOOKUP(A23,'Acompanhamento da Licitação'!$F$2:$N$1000,6,FALSE()),"") | M23: =IFERROR(VLOOKUP(A23,'Acompanhamento da Licitação'!$F$2:$N$1000,7,FALSE()),"") | N23: =IFERROR(VLOOKUP(A23,'Acompanhamento da Licitação'!$F$2:$N$1000,9,FALSE()),"") | O23: =IF(AND(D23>0,F23>0.25),"Sim","Não") -> Não | P23: =4%*E23 -> 0
F24: =IF(B24>0,(((E24*C24)-(D24*C24)-(P24*C24))/(E24*C24)),"") | G24: =IF(F24="","",IF(F24<0.2,0.05,IF(F24<0.25,0.1,IF(F24<0.3,0.15,IF(F24<0.35,0.2,IF(F24<0.45,0.25,IF(F24<0.5,0.3,IF(F24<0.6,0.35,0.4)))))))) | H24: =IFERROR(((E24*C24)-(D24*C24)-(E24*C24*4%))*G24,"") | L24: =IFERROR(VLOOKUP(A24,'Acompanhamento da Licitação'!$F$2:$N$1000,6,FALSE()),"") | M24: =IFERROR(VLOOKUP(A24,'Acompanhamento da Licitação'!$F$2:$N$1000,7,FALSE()),"") | N24: =IFERROR(VLOOKUP(A24,'Acompanhamento da Licitação'!$F$2:$N$1000,9,FALSE()),"") | O24: =IF(AND(D24>0,F24>0.25),"Sim","Não") -> Não | P24: =4%*E24 -> 0
F25: =IF(B25>0,(((E25*C25)-(D25*C25)-(P25*C25))/(E25*C25)),"") | G25: =IF(F25="","",IF(F25<0.2,0.05,IF(F25<0.25,0.1,IF(F25<0.3,0.15,IF(F25<0.35,0.2,IF(F25<0.45,0.25,IF(F25<0.5,0.3,IF(F25<0.6,0.35,0.4)))))))) | H25: =IFERROR(((E25*C25)-(D25*C25)-(E25*C25*4%))*G25,"") | L25: =IFERROR(VLOOKUP(A25,'Acompanhamento da Licitação'!$F$2:$N$1000,6,FALSE()),"") | M25: =IFERROR(VLOOKUP(A25,'Acompanhamento da Licitação'!$F$2:$N$1000,7,FALSE()),"") | N25: =IFERROR(VLOOKUP(A25,'Acompanhamento da Licitação'!$F$2:$N$1000,9,FALSE()),"") | O25: =IF(AND(D25>0,F25>0.25),"Sim","Não") -> Não | P25: =4%*E25 -> 0
F26: =IF(B26>0,(((E26*C26)-(D26*C26)-(P26*C26))/(E26*C26)),"") | G26: =IF(F26="","",IF(F26<0.2,0.05,IF(F26<0.25,0.1,IF(F26<0.3,0.15,IF(F26<0.35,0.2,IF(F26<0.45,0.25,IF(F26<0.5,0.3,IF(F26<0.6,0.35,0.4)))))))) | H26: =IFERROR(((E26*C26)-(D26*C26)-(E26*C26*4%))*G26,"") | L26: =IFERROR(VLOOKUP(A26,'Acompanhamento da Licitação'!$F$2:$N$1000,6,FALSE()),"") | M26: =IFERROR(VLOOKUP(A26,'Acompanhamento da Licitação'!$F$2:$N$1000,7,FALSE()),"") | N26: =IFERROR(VLOOKUP(A26,'Acompanhamento da Licitação'!$F$2:$N$1000,9,FALSE()),"") | O26: =IF(AND(D26>0,F26>0.25),"Sim","Não") -> Não | P26: =4%*E26 -> 0
F27: =IF(B27>0,(((E27*C27)-(D27*C27)-(P27*C27))/(E27*C27)),"") | G27: =IF(F27="","",IF(F27<0.2,0.05,IF(F27<0.25,0.1,IF(F27<0.3,0.15,IF(F27<0.35,0.2,IF(F27<0.45,0.25,IF(F27<0.5,0.3,IF(F27<0.6,0.35,0.4)))))))) | H27: =IFERROR(((E27*C27)-(D27*C27)-(E27*C27*4%))*G27,"") | L27: =IFERROR(VLOOKUP(A27,'Acompanhamento da Licitação'!$F$2:$N$1000,6,FALSE()),"") | M27: =IFERROR(VLOOKUP(A27,'Acompanhamento da Licitação'!$F$2:$N$1000,7,FALSE()),"") | N27: =IFERROR(VLOOKUP(A27,'Acompanhamento da Licitação'!$F$2:$N$1000,9,FALSE()),"") | O27: =IF(AND(D27>0,F27>0.25),"Sim","Não") -> Não | P27: =4%*E27 -> 0
F28: =IF(B28>0,(((E28*C28)-(D28*C28)-(P28*C28))/(E28*C28)),"") | G28: =IF(F28="","",IF(F28<0.2,0.05,IF(F28<0.25,0.1,IF(F28<0.3,0.15,IF(F28<0.35,0.2,IF(F28<0.45,0.25,IF(F28<0.5,0.3,IF(F28<0.6,0.35,0.4)))))))) | H28: =IFERROR(((E28*C28)-(D28*C28)-(E28*C28*4%))*G28,"") | L28: =IFERROR(VLOOKUP(A28,'Acompanhamento da Licitação'!$F$2:$N$1000,6,FALSE()),"") | M28: =IFERROR(VLOOKUP(A28,'Acompanhamento da Licitação'!$F$2:$N$1000,7,FALSE()),"") | N28: =IFERROR(VLOOKUP(A28,'Acompanhamento da Licitação'!$F$2:$N$1000,9,FALSE()),"") | O28: =IF(AND(D28>0,F28>0.25),"Sim","Não") -> Não | P28: =4%*E28 -> 0
F29: =IF(B29>0,(((E29*C29)-(D29*C29)-(P29*C29))/(E29*C29)),"") | G29: =IF(F29="","",IF(F29<0.2,0.05,IF(F29<0.25,0.1,IF(F29<0.3,0.15,IF(F29<0.35,0.2,IF(F29<0.45,0.25,IF(F29<0.5,0.3,IF(F29<0.6,0.35,0.4)))))))) | H29: =IFERROR(((E29*C29)-(D29*C29)-(E29*C29*4%))*G29,"") | L29: =IFERROR(VLOOKUP(A29,'Acompanhamento da Licitação'!$F$2:$N$1000,6,FALSE()),"") | M29: =IFERROR(VLOOKUP(A29,'Acompanhamento da Licitação'!$F$2:$N$1000,7,FALSE()),"") | N29: =IFERROR(VLOOKUP(A29,'Acompanhamento da Licitação'!$F$2:$N$1000,9,FALSE()),"") | O29: =IF(AND(D29>0,F29>0.25),"Sim","Não") -> Não | P29: =4%*E29 -> 0
F30: =IF(B30>0,(((E30*C30)-(D30*C30)-(P30*C30))/(E30*C30)),"") | G30: =IF(F30="","",IF(F30<0.2,0.05,IF(F30<0.25,0.1,IF(F30<0.3,0.15,IF(F30<0.35,0.2,IF(F30<0.45,0.25,IF(F30<0.5,0.3,IF(F30<0.6,0.35,0.4)))))))) | H30: =IFERROR(((E30*C30)-(D30*C30)-(E30*C30*4%))*G30,"") | L30: =IFERROR(VLOOKUP(A30,'Acompanhamento da Licitação'!$F$2:$N$1000,6,FALSE()),"") | M30: =IFERROR(VLOOKUP(A30,'Acompanhamento da Licitação'!$F$2:$N$1000,7,FALSE()),"") | N30: =IFERROR(VLOOKUP(A30,'Acompanhamento da Licitação'!$F$2:$N$1000,9,FALSE()),"") | O30: =IF(AND(D30>0,F30>0.25),"Sim","Não") -> Não | P30: =4%*E30 -> 0
F31: =IF(B31>0,(((E31*C31)-(D31*C31)-(P31*C31))/(E31*C31)),"") | G31: =IF(F31="","",IF(F31<0.2,0.05,IF(F31<0.25,0.1,IF(F31<0.3,0.15,IF(F31<0.35,0.2,IF(F31<0.45,0.25,IF(F31<0.5,0.3,IF(F31<0.6,0.35,0.4)))))))) | H31: =IFERROR(((E31*C31)-(D31*C31)-(E31*C31*4%))*G31,"") | L31: =IFERROR(VLOOKUP(A31,'Acompanhamento da Licitação'!$F$2:$N$1000,6,FALSE()),"") | M31: =IFERROR(VLOOKUP(A31,'Acompanhamento da Licitação'!$F$2:$N$1000,7,FALSE()),"") | N31: =IFERROR(VLOOKUP(A31,'Acompanhamento da Licitação'!$F$2:$N$1000,9,FALSE()),"") | O31: =IF(AND(D31>0,F31>0.25),"Sim","Não") -> Não | P31: =4%*E31 -> 0
F32: =IF(B32>0,(((E32*C32)-(D32*C32)-(P32*C32))/(E32*C32)),"") | G32: =IF(F32="","",IF(F32<0.2,0.05,IF(F32<0.25,0.1,IF(F32<0.3,0.15,IF(F32<0.35,0.2,IF(F32<0.45,0.25,IF(F32<0.5,0.3,IF(F32<0.6,0.35,0.4)))))))) | H32: =IFERROR(((E32*C32)-(D32*C32)-(E32*C32*4%))*G32,"") | L32: =IFERROR(VLOOKUP(A32,'Acompanhamento da Licitação'!$F$2:$N$1000,6,FALSE()),"") | M32: =IFERROR(VLOOKUP(A32,'Acompanhamento da Licitação'!$F$2:$N$1000,7,FALSE()),"") | N32: =IFERROR(VLOOKUP(A32,'Acompanhamento da Licitação'!$F$2:$N$1000,9,FALSE()),"") | O32: =IF(AND(D32>0,F32>0.25),"Sim","Não") -> Não | P32: =4%*E32 -> 0
F33: =IF(B33>0,(((E33*C33)-(D33*C33)-(P33*C33))/(E33*C33)),"") | G33: =IF(F33="","",IF(F33<0.2,0.05,IF(F33<0.25,0.1,IF(F33<0.3,0.15,IF(F33<0.35,0.2,IF(F33<0.45,0.25,IF(F33<0.5,0.3,IF(F33<0.6,0.35,0.4)))))))) | H33: =IFERROR(((E33*C33)-(D33*C33)-(E33*C33*4%))*G33,"") | L33: =IFERROR(VLOOKUP(A33,'Acompanhamento da Licitação'!$F$2:$N$1000,6,FALSE()),"") | M33: =IFERROR(VLOOKUP(A33,'Acompanhamento da Licitação'!$F$2:$N$1000,7,FALSE()),"") | N33: =IFERROR(VLOOKUP(A33,'Acompanhamento da Licitação'!$F$2:$N$1000,9,FALSE()),"") | O33: =IF(AND(D33>0,F33>0.25),"Sim","Não") -> Não | P33: =4%*E33 -> 0
... F500: =IF(B500>0,(((E500*C500)-(D500*C500)-(P500*C500))/(E500*C500)),"") | G500: =IF(F500="","",IF(F500<0.2,0.05,IF(F500<0.25,0.1,IF(F500<0.3,0.15,IF(F500<0.35,0.2,IF(F500<0.45,0.25,IF(F500<0.5,0.3,IF(F500<0.6,0.35,0.4)))))))) | H500: =IFERROR(((E500*C500)-(D500*C500)-(E500*C500*4%))*G500,"") | L500: =IFERROR(VLOOKUP(A500,'Acompanhamento da Licitação'!$F$2:$N$1000,6,FALSE()),"") | M500: =IFERROR(VLOOKUP(A500,'Acompanhamento da Licitação'!$F$2:$N$1000,7,FALSE()),"") | N500: =IFERROR(VLOOKUP(A500,'Acompanhamento da Licitação'!$F$2:$N$1000,9,FALSE()),"") | O500: =IF(AND(D500>0,F500>0.25),"Sim","Não") -> Não | P500: =4%*E500 -> 0
L501: =IFERROR(VLOOKUP(A501,'Acompanhamento da Licitação'!$F$2:$N$1000,6,FALSE()),"") | M501: =IFERROR(VLOOKUP(A501,'Acompanhamento da Licitação'!$F$2:$N$1000,7,FALSE()),"") | N501: =IFERROR(VLOOKUP(A501,'Acompanhamento da Licitação'!$F$2:$N$1000,9,FALSE()),"")
L502: =IFERROR(VLOOKUP(A502,'Acompanhamento da Licitação'!$F$2:$N$1000,6,FALSE()),"") | M502: =IFERROR(VLOOKUP(A502,'Acompanhamento da Licitação'!$F$2:$N$1000,7,FALSE()),"") | N502: =IFERROR(VLOOKUP(A502,'Acompanhamento da Licitação'!$F$2:$N$1000,9,FALSE()),"")
L503: =IFERROR(VLOOKUP(A503,'Acompanhamento da Licitação'!$F$2:$N$1000,6,FALSE()),"") | M503: =IFERROR(VLOOKUP(A503,'Acompanhamento da Licitação'!$F$2:$N$1000,7,FALSE()),"") | N503: =IFERROR(VLOOKUP(A503,'Acompanhamento da Licitação'!$F$2:$N$1000,9,FALSE()),"")
L504: =IFERROR(VLOOKUP(A504,'Acompanhamento da Licitação'!$F$2:$N$1000,6,FALSE()),"") | M504: =IFERROR(VLOOKUP(A504,'Acompanhamento da Licitação'!$F$2:$N$1000,7,FALSE()),"") | N504: =IFERROR(VLOOKUP(A504,'Acompanhamento da Licitação'!$F$2:$N$1000,9,FALSE()),"")
L505: =IFERROR(VLOOKUP(A505,'Acompanhamento da Licitação'!$F$2:$N$1000,6,FALSE()),"") | M505: =IFERROR(VLOOKUP(A505,'Acompanhamento da Licitação'!$F$2:$N$1000,7,FALSE()),"") | N505: =IFERROR(VLOOKUP(A505,'Acompanhamento da Licitação'!$F$2:$N$1000,9,FALSE()),"")
L506: =IFERROR(VLOOKUP(A506,'Acompanhamento da Licitação'!$F$2:$N$1000,6,FALSE()),"") | M506: =IFERROR(VLOOKUP(A506,'Acompanhamento da Licitação'!$F$2:$N$1000,7,FALSE()),"") | N506: =IFERROR(VLOOKUP(A506,'Acompanhamento da Licitação'!$F$2:$N$1000,9,FALSE()),"")
L507: =IFERROR(VLOOKUP(A507,'Acompanhamento da Licitação'!$F$2:$N$1000,6,FALSE()),"") | M507: =IFERROR(VLOOKUP(A507,'Acompanhamento da Licitação'!$F$2:$N$1000,7,FALSE()),"") | N507: =IFERROR(VLOOKUP(A507,'Acompanhamento da Licitação'!$F$2:$N$1000,9,FALSE()),"")
L508: =IFERROR(VLOOKUP(A508,'Acompanhamento da Licitação'!$F$2:$N$1000,6,FALSE()),"") | M508: =IFERROR(VLOOKUP(A508,'Acompanhamento da Licitação'!$F$2:$N$1000,7,FALSE()),"") | N508: =IFERROR(VLOOKUP(A508,'Acompanhamento da Licitação'!$F$2:$N$1000,9,FALSE()),"")
L509: =IFERROR(VLOOKUP(A509,'Acompanhamento da Licitação'!$F$2:$N$1000,6,FALSE()),"") | M509: =IFERROR(VLOOKUP(A509,'Acompanhamento da Licitação'!$F$2:$N$1000,7,FALSE()),"") | N509: =IFERROR(VLOOKUP(A509,'Acompanhamento da Licitação'!$F$2:$N$1000,9,FALSE()),"")
L510: =IFERROR(VLOOKUP(A510,'Acompanhamento da Licitação'!$F$2:$N$1000,6,FALSE()),"") | M510: =IFERROR(VLOOKUP(A510,'Acompanhamento da Licitação'!$F$2:$N$1000,7,FALSE()),"") | N510: =IFERROR(VLOOKUP(A510,'Acompanhamento da Licitação'!$F$2:$N$1000,9,FALSE()),"")
L511: =IFERROR(VLOOKUP(A511,'Acompanhamento da Licitação'!$F$2:$N$1000,6,FALSE()),"") | M511: =IFERROR(VLOOKUP(A511,'Acompanhamento da Licitação'!$F$2:$N$1000,7,FALSE()),"") | N511: =IFERROR(VLOOKUP(A511,'Acompanhamento da Licitação'!$F$2:$N$1000,9,FALSE()),"")
L512: =IFERROR(VLOOKUP(A512,'Acompanhamento da Licitação'!$F$2:$N$1000,6,FALSE()),"") | M512: =IFERROR(VLOOKUP(A512,'Acompanhamento da Licitação'!$F$2:$N$1000,7,FALSE()),"") | N512: =IFERROR(VLOOKUP(A512,'Acompanhamento da Licitação'!$F$2:$N$1000,9,FALSE()),"")
... L1050: =IFERROR(VLOOKUP(A1050,'Acompanhamento da Licitação'!$F$2:$N$1000,6,FALSE()),"") | M1050: =IFERROR(VLOOKUP(A1050,'Acompanhamento da Licitação'!$F$2:$N$1000,7,FALSE()),"") | N1050: =IFERROR(VLOOKUP(A1050,'Acompanhamento da Licitação'!$F$2:$N$1000,9,FALSE()),"")

Sheet Prosposta Inicial
A1: Repetições | B1: Junção | C1: Preço Preenchido | D1: Ordem dos Lotes | G1: =IF(M2>0,M2,"") -> 40.127.372 RICHARD HENRIQUE VERNILLO | K1: =IF(O2>0,O2,"") | M1: Empresa | O1: Solicitante | R1: 58.603.996 LILIAN MARINO AMARAL LOPES
A2: =COUNTIF($C$2:C2,C2) -> 1 | B2: =IFERROR(CONCATENATE(C2,A2),"") -> 1 | C2: =IFERROR(VLOOKUP(D2,'Planilha de Cadastro - Previsão'!$A$2:$O$1000,15,FALSE()),"") | D2: 1 | G2: =IF(M5>0,M5,"") -> Rua Antonio Teodoro Nogueira, 1016 | K2: =IF(O5>0,O5,"") | M2: 40.127.372 RICHARD HENRIQUE VERNILLO | R2: 40.127.372 RICHARD HENRIQUE VERNILLO
A3: =COUNTIF($C$2:C3,C3) -> 2 | B3: =IFERROR(CONCATENATE(C3,A3),"") -> 2 | C3: =IFERROR(VLOOKUP(D3,'Planilha de Cadastro - Previsão'!$A$2:$O$1000,15,FALSE()),"") | D3: 2 | G3: =IF(M8>0,M8,"") -> Jaborandi - São Paulo - Brasil | K3: =IF(O8>0,O8,"") | R3: 56.386.309 STEFFAN DIORGY SILVA VERNILLO
A4: =COUNTIF($C$2:C4,C4) -> 3 | B4: =IFERROR(CONCATENATE(C4,A4),"") -> 3 | C4: =IFERROR(VLOOKUP(D4,'Planilha de Cadastro - Previsão'!$A$2:$O$1000,15,FALSE()),"") | D4: 3 | G4: =IF(M11>0,M11,"") -> 14775-000 | K4: =IF(O11>0,O11,"") | M4: Endereço | O4: Endereço
A5: =COUNTIF($C$2:C5,C5) -> 4 | B5: =IFERROR(CONCATENATE(C5,A5),"") -> 4 | C5: =IFERROR(VLOOKUP(D5,'Planilha de Cadastro - Previsão'!$A$2:$O$1000,15,FALSE()),"") | D5: 4 | G5: =IF(M14>0,M14,"") -> 40.127.372/0001-06 | K5: =IF(O14>0,O14,"") | M5: =IF(M2="58.603.996 LILIAN MARINO AMARAL LOPES","Rua Luis Daniel 160",IF(M2="40.127.372 RICHARD HENRIQUE VERNILLO","Rua Antonio Teodoro Nogueira, 1016","Rua Inacio Maximo Diniz Junqueira, 527")) -> Rua Antonio Teodoro Nogueira, 1016
A6: =COUNTIF($C$2:C6,C6) -> 5 | B6: =IFERROR(CONCATENATE(C6,A6),"") -> 5 | C6: =IFERROR(VLOOKUP(D6,'Planilha de Cadastro - Previsão'!$A$2:$O$1000,15,FALSE()),"") | D6: 5 | G6: =IF(M20>0,M20,"") -> contato@mabus.com.br | S6: =UPPER(R6)
A7: =COUNTIF($C$2:C7,C7) -> 6 | B7: =IFERROR(CONCATENATE(C7,A7),"") -> 6 | C7: =IFERROR(VLOOKUP(D7,'Planilha de Cadastro - Previsão'!$A$2:$O$1000,15,FALSE()),"") | D7: 6 | G7: =IF(M17>0,M17,"") | J7: Data da Proposta: | K7: =TODAY() -> 45997 | M7: Cidade, Estado e País | O7: Cidade, Estado e País
A8: =COUNTIF($C$2:C8,C8) -> 7 | B8: =IFERROR(CONCATENATE(C8,A8),"") -> 7 | C8: =IFERROR(VLOOKUP(D8,'Planilha de Cadastro - Previsão'!$A$2:$O$1000,15,FALSE()),"") | D8: 7 | M8: Jaborandi - São Paulo - Brasil
A9: =COUNTIF($C$2:C9,C9) -> 8 | B9: =IFERROR(CONCATENATE(C9,A9),"") -> 8 | C9: =IFERROR(VLOOKUP(D9,'Planilha de Cadastro - Previsão'!$A$2:$O$1000,15,FALSE()),"") | D9: 8 | G9: Lote | H9: Item | I9: Quantidade | J9: Valor da Venda (UN.) | K9: Marca/Modelo
A10: =COUNTIF($C$2:C10,C10) -> 9 | B10: =IFERROR(CONCATENATE(C10,A10),"") -> 9 | C10: =IFERROR(VLOOKUP(D10,'Planilha de Cadastro - Previsão'!$A$2:$O$1000,15,FALSE()),"") | D10: 9 | G10: =IFERROR((VLOOKUP(CONCATENATE("Sim",D2),$B$2:$D$1000,3,FALSE())),"") | H10: =IFERROR((VLOOKUP(G10,'Planilha de Cadastro - Previsão'!$A$2:$N$1100,2,FALSE()))," ") | I10: =IFERROR((VLOOKUP(G10,'Planilha de Cadastro - Previsão'!$A$2:$N$1100,3,FALSE()))," ") | J10: =IFERROR((VLOOKUP(G10,'Planilha de Cadastro - Previsão'!$A$2:$N$1100,5,FALSE()))," ") | K10: =IFERROR((VLOOKUP(G10,'Planilha de Cadastro - Previsão'!$A$2:$N$1100,9,FALSE()))," ") | M10: CEP | O10: CEP
A11: =COUNTIF($C$2:C11,C11) -> 10 | B11: =IFERROR(CONCATENATE(C11,A11),"") -> 10 | C11: =IFERROR(VLOOKUP(D11,'Planilha de Cadastro - Previsão'!$A$2:$O$1000,15,FALSE()),"") | D11: 10 | G11: =IFERROR((VLOOKUP(CONCATENATE("Sim",D3),$B$2:$D$1000,3,FALSE())),"") | H11: =IFERROR((VLOOKUP(G11,'Planilha de Cadastro - Previsão'!$A$2:$N$1100,2,FALSE()))," ") | I11: =IFERROR((VLOOKUP(G11,'Planilha de Cadastro - Previsão'!$A$2:$N$1100,3,FALSE()))," ") | J11: =IFERROR((VLOOKUP(G11,'Planilha de Cadastro - Previsão'!$A$2:$N$1100,5,FALSE()))," ") | K11: =IFERROR((VLOOKUP(G11,'Planilha de Cadastro - Previsão'!$A$2:$N$1100,9,FALSE()))," ") | M11: 14775-000
A12: =COUNTIF($C$2:C12,C12) -> 11 | B12: =IFERROR(CONCATENATE(C12,A12),"") -> 11 | C12: =IFERROR(VLOOKUP(D12,'Planilha de Cadastro - Previsão'!$A$2:$O$1000,15,FALSE()),"") | D12: 11 | G12: =IFERROR((VLOOKUP(CONCATENATE("Sim",D4),$B$2:$D$1000,3,FALSE())),"") | H12: =IFERROR((VLOOKUP(G12,'Planilha de Cadastro - Previsão'!$A$2:$N$1100,2,FALSE()))," ") | I12: =IFERROR((VLOOKUP(G12,'Planilha de Cadastro - Previsão'!$A$2:$N$1100,3,FALSE()))," ") | J12: =IFERROR((VLOOKUP(G12,'Planilha de Cadastro - Previsão'!$A$2:$N$1100,5,FALSE()))," ") | K12: =IFERROR((VLOOKUP(G12,'Planilha de Cadastro - Previsão'!$A$2:$N$1100,9,FALSE()))," ")
A13: =COUNTIF($C$2:C13,C13) -> 12 | B13: =IFERROR(CONCATENATE(C13,A13),"") -> 12 | C13: =IFERROR(VLOOKUP(D13,'Planilha de Cadastro - Previsão'!$A$2:$O$1000,15,FALSE()),"") | D13: 12 | G13: =IFERROR((VLOOKUP(CONCATENATE("Sim",D5),$B$2:$D$1000,3,FALSE())),"") | H13: =IFERROR((VLOOKUP(G13,'Planilha de Cadastro - Previsão'!$A$2:$N$1100,2,FALSE()))," ") | I13: =IFERROR((VLOOKUP(G13,'Planilha de Cadastro - Previsão'!$A$2:$N$1100,3,FALSE()))," ") | J13: =IFERROR((VLOOKUP(G13,'Planilha de Cadastro - Previsão'!$A$2:$N$1100,5,FALSE()))," ") | K13: =IFERROR((VLOOKUP(G13,'Planilha de Cadastro - Previsão'!$A$2:$N$1100,9,FALSE()))," ") | M13: CNPJ | O13: CNPJ
A14: =COUNTIF($C$2:C14,C14) -> 13 | B14: =IFERROR(CONCATENATE(C14,A14),"") -> 13 | C14: =IFERROR(VLOOKUP(D14,'Planilha de Cadastro - Previsão'!$A$2:$O$1000,15,FALSE()),"") | D14: 13 | G14: =IFERROR((VLOOKUP(CONCATENATE("Sim",D6),$B$2:$D$1000,3,FALSE())),"") | H14: =IFERROR((VLOOKUP(G14,'Planilha de Cadastro - Previsão'!$A$2:$N$1100,2,FALSE()))," ") | I14: =IFERROR((VLOOKUP(G14,'Planilha de Cadastro - Previsão'!$A$2:$N$1100,3,FALSE()))," ") | J14: =IFERROR((VLOOKUP(G14,'Planilha de Cadastro - Previsão'!$A$2:$N$1100,5,FALSE()))," ") | K14: =IFERROR((VLOOKUP(G14,'Planilha de Cadastro - Previsão'!$A$2:$N$1100,9,FALSE()))," ") | M14: =IF(M2="58.603.996 LILIAN MARINO AMARAL LOPES","58.603.996/0001-00",IF(M2="40.127.372 RICHARD HENRIQUE VERNILLO","40.127.372/0001-06","56.386.309/0001-16")) -> 40.127.372/0001-06
A15: =COUNTIF($C$2:C15,C15) -> 14 | B15: =IFERROR(CONCATENATE(C15,A15),"") -> 14 | C15: =IFERROR(VLOOKUP(D15,'Planilha de Cadastro - Previsão'!$A$2:$O$1000,15,FALSE()),"") | D15: 14 | G15: =IFERROR((VLOOKUP(CONCATENATE("Sim",D7),$B$2:$D$1000,3,FALSE())),"") | H15: =IFERROR((VLOOKUP(G15,'Planilha de Cadastro - Previsão'!$A$2:$N$1100,2,FALSE()))," ") | I15: =IFERROR((VLOOKUP(G15,'Planilha de Cadastro - Previsão'!$A$2:$N$1100,3,FALSE()))," ") | J15: =IFERROR((VLOOKUP(G15,'Planilha de Cadastro - Previsão'!$A$2:$N$1100,5,FALSE()))," ") | K15: =IFERROR((VLOOKUP(G15,'Planilha de Cadastro - Previsão'!$A$2:$N$1100,9,FALSE()))," ")
A16: =COUNTIF($C$2:C16,C16) -> 15 | B16: =IFERROR(CONCATENATE(C16,A16),"") -> 15 | C16: =IFERROR(VLOOKUP(D16,'Planilha de Cadastro - Previsão'!$A$2:$O$1000,15,FALSE()),"") | D16: 15 | G16: =IFERROR((VLOOKUP(CONCATENATE("Sim",D8),$B$2:$D$1000,3,FALSE())),"") | H16: =IFERROR((VLOOKUP(G16,'Planilha de Cadastro - Previsão'!$A$2:$N$1100,2,FALSE()))," ") | I16: =IFERROR((VLOOKUP(G16,'Planilha de Cadastro - Previsão'!$A$2:$N$1100,3,FALSE()))," ") | J16: =IFERROR((VLOOKUP(G16,'Planilha de Cadastro - Previsão'!$A$2:$N$1100,5,FALSE()))," ") | K16: =IFERROR((VLOOKUP(G16,'Planilha de Cadastro - Previsão'!$A$2:$N$1100,9,FALSE()))," ") | M16: Telefone | O16: Telefone
A17: =COUNTIF($C$2:C17,C17) -> 16 | B17: =IFERROR(CONCATENATE(C17,A17),"") -> 16 | C17: =IFERROR(VLOOKUP(D17,'Planilha de Cadastro - Previsão'!$A$2:$O$1000,15,FALSE()),"") | D17: 16 | G17: =IFERROR((VLOOKUP(CONCATENATE("Sim",D9),$B$2:$D$1000,3,FALSE())),"") | H17: =IFERROR((VLOOKUP(G17,'Planilha de Cadastro - Previsão'!$A$2:$N$1100,2,FALSE()))," ") | I17: =IFERROR((VLOOKUP(G17,'Planilha de Cadastro - Previsão'!$A$2:$N$1100,3,FALSE()))," ") | J17: =IFERROR((VLOOKUP(G17,'Planilha de Cadastro - Previsão'!$A$2:$N$1100,5,FALSE()))," ") | K17: =IFERROR((VLOOKUP(G17,'Planilha de Cadastro - Previsão'!$A$2:$N$1100,9,FALSE()))," ")
A18: =COUNTIF($C$2:C18,C18) -> 17 | B18: =IFERROR(CONCATENATE(C18,A18),"") -> 17 | C18: =IFERROR(VLOOKUP(D18,'Planilha de Cadastro - Previsão'!$A$2:$O$1000,15,FALSE()),"") | D18: 17 | G18: =IFERROR((VLOOKUP(CONCATENATE("Sim",D10),$B$2:$D$1000,3,FALSE())),"") | H18: =IFERROR((VLOOKUP(G18,'Planilha de Cadastro - Previsão'!$A$2:$N$1100,2,FALSE()))," ") | I18: =IFERROR((VLOOKUP(G18,'Planilha de Cadastro - Previsão'!$A$2:$N$1100,3,FALSE()))," ") | J18: =IFERROR((VLOOKUP(G18,'Planilha de Cadastro - Previsão'!$A$2:$N$1100,5,FALSE()))," ") | K18: =IFERROR((VLOOKUP(G18,'Planilha de Cadastro - Previsão'!$A$2:$N$1100,9,FALSE()))," ")
A19: =COUNTIF($C$2:C19,C19) -> 18 | B19: =IFERROR(CONCATENATE(C19,A19),"") -> 18 | C19: =IFERROR(VLOOKUP(D19,'Planilha de Cadastro - Previsão'!$A$2:$O$1000,15,FALSE()),"") | D19: 18 | G19: =IFERROR((VLOOKUP(CONCATENATE("Sim",D11),$B$2:$D$1000,3,FALSE())),"") | H19: =IFERROR((VLOOKUP(G19,'Planilha de Cadastro - Previsão'!$A$2:$N$1100,2,FALSE()))," ") | I19: =IFERROR((VLOOKUP(G19,'Planilha de Cadastro - Previsão'!$A$2:$N$1100,3,FALSE()))," ") | J19: =IFERROR((VLOOKUP(G19,'Planilha de Cadastro - Previsão'!$A$2:$N$1100,5,FALSE()))," ") | K19: =IFERROR((VLOOKUP(G19,'Planilha de Cadastro - Previsão'!$A$2:$N$1100,9,FALSE()))," ") | M19: Email | O19: Email
A20: =COUNTIF($C$2:C20,C20) -> 19 | B20: =IFERROR(CONCATENATE(C20,A20),"") -> 19 | C20: =IFERROR(VLOOKUP(D20,'Planilha de Cadastro - Previsão'!$A$2:$O$1000,15,FALSE()),"") | D20: 19 | G20: =IFERROR((VLOOKUP(CONCATENATE("Sim",D12),$B$2:$D$1000,3,FALSE())),"") | H20: =IFERROR((VLOOKUP(G20,'Planilha de Cadastro - Previsão'!$A$2:$N$1100,2,FALSE()))," ") | I20: =IFERROR((VLOOKUP(G20,'Planilha de Cadastro - Previsão'!$A$2:$N$1100,3,FALSE()))," ") | J20: =IFERROR((VLOOKUP(G20,'Planilha de Cadastro - Previsão'!$A$2:$N$1100,5,FALSE()))," ") | K20: =IFERROR((VLOOKUP(G20,'Planilha de Cadastro - Previsão'!$A$2:$N$1100,9,FALSE()))," ") | M20: =IF(M2="58.603.996 LILIAN MARINO AMARAL LOPES","lia@mabus.com.br",IF(M8="40.127.372 RICHARD HENRIQUE VERNILLO","richard@mabus.com.br","contato@mabus.com.br")) -> contato@mabus.com.br
A21: =COUNTIF($C$2:C21,C21) -> 20 | B21: =IFERROR(CONCATENATE(C21,A21),"") -> 20 | C21: =IFERROR(VLOOKUP(D21,'Planilha de Cadastro - Previsão'!$A$2:$O$1000,15,FALSE()),"") | D21: 20 | G21: =IFERROR((VLOOKUP(CONCATENATE("Sim",D13),$B$2:$D$1000,3,FALSE())),"") | H21: =IFERROR((VLOOKUP(G21,'Planilha de Cadastro - Previsão'!$A$2:$N$1100,2,FALSE()))," ") | I21: =IFERROR((VLOOKUP(G21,'Planilha de Cadastro - Previsão'!$A$2:$N$1100,3,FALSE()))," ") | J21: =IFERROR((VLOOKUP(G21,'Planilha de Cadastro - Previsão'!$A$2:$N$1100,5,FALSE()))," ") | K21: =IFERROR((VLOOKUP(G21,'Planilha de Cadastro - Previsão'!$A$2:$N$1100,9,FALSE()))," ")
A22: =COUNTIF($C$2:C22,C22) -> 21 | B22: =IFERROR(CONCATENATE(C22,A22),"") -> 21 | C22: =IFERROR(VLOOKUP(D22,'Planilha de Cadastro - Previsão'!$A$2:$O$1000,15,FALSE()),"") | D22: 21 | G22: =IFERROR((VLOOKUP(CONCATENATE("Sim",D14),$B$2:$D$1000,3,FALSE())),"") | H22: =IFERROR((VLOOKUP(G22,'Planilha de Cadastro - Previsão'!$A$2:$N$1100,2,FALSE()))," ") | I22: =IFERROR((VLOOKUP(G22,'Planilha de Cadastro - Previsão'!$A$2:$N$1100,3,FALSE()))," ") | J22: =IFERROR((VLOOKUP(G22,'Planilha de Cadastro - Previsão'!$A$2:$N$1100,5,FALSE()))," ") | K22: =IFERROR((VLOOKUP(G22,'Planilha de Cadastro - Previsão'!$A$2:$N$1100,9,FALSE()))," ")
A23: =COUNTIF($C$2:C23,C23) -> 22 | B23: =IFERROR(CONCATENATE(C23,A23),"") -> 22 | C23: =IFERROR(VLOOKUP(D23,'Planilha de Cadastro - Previsão'!$A$2:$O$1000,15,FALSE()),"") | D23: 22 | G23: =IFERROR((VLOOKUP(CONCATENATE("Sim",D15),$B$2:$D$1000,3,FALSE())),"") | H23: =IFERROR((VLOOKUP(G23,'Planilha de Cadastro - Previsão'!$A$2:$N$1100,2,FALSE()))," ") | I23: =IFERROR((VLOOKUP(G23,'Planilha de Cadastro - Previsão'!$A$2:$N$1100,3,FALSE()))," ") | J23: =IFERROR((VLOOKUP(G23,'Planilha de Cadastro - Previsão'!$A$2:$N$1100,5,FALSE()))," ") | K23: =IFERROR((VLOOKUP(G23,'Planilha de Cadastro - Previsão'!$A$2:$N$1100,9,FALSE()))," ")
A24: =COUNTIF($C$2:C24,C24) -> 23 | B24: =IFERROR(CONCATENATE(C24,A24),"") -> 23 | C24: =IFERROR(VLOOKUP(D24,'Planilha de Cadastro - Previsão'!$A$2:$O$1000,15,FALSE()),"") | D24: 23 | G24: =IFERROR((VLOOKUP(CONCATENATE("Sim",D16),$B$2:$D$1000,3,FALSE())),"") | H24: =IFERROR((VLOOKUP(G24,'Planilha de Cadastro - Previsão'!$A$2:$N$1100,2,FALSE()))," ") | I24: =IFERROR((VLOOKUP(G24,'Planilha de Cadastro - Previsão'!$A$2:$N$1100,3,FALSE()))," ") | J24: =IFERROR((VLOOKUP(G24,'Planilha de Cadastro - Previsão'!$A$2:$N$1100,5,FALSE()))," ") | K24: =IFERROR((VLOOKUP(G24,'Planilha de Cadastro - Previsão'!$A$2:$N$1100,9,FALSE()))," ")
A25: =COUNTIF($C$2:C25,C25) -> 24 | B25: =IFERROR(CONCATENATE(C25,A25),"") -> 24 | C25: =IFERROR(VLOOKUP(D25,'Planilha de Cadastro - Previsão'!$A$2:$O$1000,15,FALSE()),"") | D25: 24 | G25: =IFERROR((VLOOKUP(CONCATENATE("Sim",D17),$B$2:$D$1000,3,FALSE())),"") | H25: =IFERROR((VLOOKUP(G25,'Planilha de Cadastro - Previsão'!$A$2:$N$1100,2,FALSE()))," ") | I25: =IFERROR((VLOOKUP(G25,'Planilha de Cadastro - Previsão'!$A$2:$N$1100,3,FALSE()))," ") | J25: =IFERROR((VLOOKUP(G25,'Planilha de Cadastro - Previsão'!$A$2:$N$1100,5,FALSE()))," ") | K25: =IFERROR((VLOOKUP(G25,'Planilha de Cadastro - Previsão'!$A$2:$N$1100,9,FALSE()))," ")
A26: =COUNTIF($C$2:C26,C26) -> 25 | B26: =IFERROR(CONCATENATE(C26,A26),"") -> 25 | C26: =IFERROR(VLOOKUP(D26,'Planilha de Cadastro - Previsão'!$A$2:$O$1000,15,FALSE()),"") | D26: 25 | G26: =IFERROR((VLOOKUP(CONCATENATE("Sim",D18),$B$2:$D$1000,3,FALSE())),"") | H26: =IFERROR((VLOOKUP(G26,'Planilha de Cadastro - Previsão'!$A$2:$N$1100,2,FALSE()))," ") | I26: =IFERROR((VLOOKUP(G26,'Planilha de Cadastro - Previsão'!$A$2:$N$1100,3,FALSE()))," ") | J26: =IFERROR((VLOOKUP(G26,'Planilha de Cadastro - Previsão'!$A$2:$N$1100,5,FALSE()))," ") | K26: =IFERROR((VLOOKUP(G26,'Planilha de Cadastro - Previsão'!$A$2:$N$1100,9,FALSE()))," ")
A27: =COUNTIF($C$2:C27,C27) -> 26 | B27: =IFERROR(CONCATENATE(C27,A27),"") -> 26 | C27: =IFERROR(VLOOKUP(D27,'Planilha de Cadastro - Previsão'!$A$2:$O$1000,15,FALSE()),"") | D27: 26 | G27: =IFERROR((VLOOKUP(CONCATENATE("Sim",D19),$B$2:$D$1000,3,FALSE())),"") | H27: =IFERROR((VLOOKUP(G27,'Planilha de Cadastro - Previsão'!$A$2:$N$1100,2,FALSE()))," ") | I27: =IFERROR((VLOOKUP(G27,'Planilha de Cadastro - Previsão'!$A$2:$N$1100,3,FALSE()))," ") | J27: =IFERROR((VLOOKUP(G27,'Planilha de Cadastro - Previsão'!$A$2:$N$1100,5,FALSE()))," ") | K27: =IFERROR((VLOOKUP(G27,'Planilha de Cadastro - Previsão'!$A$2:$N$1100,9,FALSE()))," ")
A28: =COUNTIF($C$2:C28,C28) -> 27 | B28: =IFERROR(CONCATENATE(C28,A28),"") -> 27 | C28: =IFERROR(VLOOKUP(D28,'Planilha de Cadastro - Previsão'!$A$2:$O$1000,15,FALSE()),"") | D28: 27 | G28: =IFERROR((VLOOKUP(CONCATENATE("Sim",D20),$B$2:$D$1000,3,FALSE())),"") | H28: =IFERROR((VLOOKUP(G28,'Planilha de Cadastro - Previsão'!$A$2:$N$1100,2,FALSE()))," ") | I28: =IFERROR((VLOOKUP(G28,'Planilha de Cadastro - Previsão'!$A$2:$N$1100,3,FALSE()))," ") | J28: =IFERROR((VLOOKUP(G28,'Planilha de Cadastro - Previsão'!$A$2:$N$1100,5,FALSE()))," ") | K28: =IFERROR((VLOOKUP(G28,'Planilha de Cadastro - Previsão'!$A$2:$N$1100,9,FALSE()))," ")
A29: =COUNTIF($C$2:C29,C29) -> 28 | B29: =IFERROR(CONCATENATE(C29,A29),"") -> 28 | C29: =IFERROR(VLOOKUP(D29,'Planilha de Cadastro - Previsão'!$A$2:$O$1000,15,FALSE()),"") | D29: 28 | G29: =IFERROR((VLOOKUP(CONCATENATE("Sim",D21),$B$2:$D$1000,3,FALSE())),"") | H29: =IFERROR((VLOOKUP(G29,'Planilha de Cadastro - Previsão'!$A$2:$N$1100,2,FALSE()))," ") | I29: =IFERROR((VLOOKUP(G29,'Planilha de Cadastro - Previsão'!$A$2:$N$1100,3,FALSE()))," ") | J29: =IFERROR((VLOOKUP(G29,'Planilha de Cadastro - Previsão'!$A$2:$N$1100,5,FALSE()))," ") | K29: =IFERROR((VLOOKUP(G29,'Planilha de Cadastro - Previsão'!$A$2:$N$1100,9,FALSE()))," ")
A30: =COUNTIF($C$2:C30,C30) -> 29 | B30: =IFERROR(CONCATENATE(C30,A30),"") -> 29 | C30: =IFERROR(VLOOKUP(D30,'Planilha de Cadastro - Previsão'!$A$2:$O$1000,15,FALSE()),"") | D30: 29 | G30: =IFERROR((VLOOKUP(CONCATENATE("Sim",D22),$B$2:$D$1000,3,FALSE())),"") | H30: =IFERROR((VLOOKUP(G30,'Planilha de Cadastro - Previsão'!$A$2:$N$1100,2,FALSE()))," ") | I30: =IFERROR((VLOOKUP(G30,'Planilha de Cadastro - Previsão'!$A$2:$N$1100,3,FALSE()))," ") | J30: =IFERROR((VLOOKUP(G30,'Planilha de Cadastro - Previsão'!$A$2:$N$1100,5,FALSE()))," ") | K30: =IFERROR((VLOOKUP(G30,'Planilha de Cadastro - Previsão'!$A$2:$N$1100,9,FALSE()))," ")
A31: =COUNTIF($C$2:C31,C31) -> 30 | B31: =IFERROR(CONCATENATE(C31,A31),"") -> 30 | C31: =IFERROR(VLOOKUP(D31,'Planilha de Cadastro - Previsão'!$A$2:$O$1000,15,FALSE()),"") | D31: 30 | G31: =IFERROR((VLOOKUP(CONCATENATE("Sim",D23),$B$2:$D$1000,3,FALSE())),"") | H31: =IFERROR((VLOOKUP(G31,'Planilha de Cadastro - Previsão'!$A$2:$N$1100,2,FALSE()))," ") | I31: =IFERROR((VLOOKUP(G31,'Planilha de Cadastro - Previsão'!$A$2:$N$1100,3,FALSE()))," ") | J31: =IFERROR((VLOOKUP(G31,'Planilha de Cadastro - Previsão'!$A$2:$N$1100,5,FALSE()))," ") | K31: =IFERROR((VLOOKUP(G31,'Planilha de Cadastro - Previsão'!$A$2:$N$1100,9,FALSE()))," ")
A32: =COUNTIF($C$2:C32,C32) -> 31 | B32: =IFERROR(CONCATENATE(C32,A32),"") -> 31 | C32: =IFERROR(VLOOKUP(D32,'Planilha de Cadastro - Previsão'!$A$2:$O$1000,15,FALSE()),"") | D32: 31 | G32: =IFERROR((VLOOKUP(CONCATENATE("Sim",D24),$B$2:$D$1000,3,FALSE())),"") | H32: =IFERROR((VLOOKUP(G32,'Planilha de Cadastro - Previsão'!$A$2:$N$1100,2,FALSE()))," ") | I32: =IFERROR((VLOOKUP(G32,'Planilha de Cadastro - Previsão'!$A$2:$N$1100,3,FALSE()))," ") | J32: =IFERROR((VLOOKUP(G32,'Planilha de Cadastro - Previsão'!$A$2:$N$1100,5,FALSE()))," ") | K32: =IFERROR((VLOOKUP(G32,'Planilha de Cadastro - Previsão'!$A$2:$N$1100,9,FALSE()))," ")
... A503: =COUNTIF($C$2:C503,C503) -> 502 | B503: =IFERROR(CONCATENATE(C503,A503),"") -> 502 | C503: =IFERROR(VLOOKUP(D503,'Planilha de Cadastro - Previsão'!$A$2:$O$1000,15,FALSE()),"") | D503: 502 | G503: =IFERROR((VLOOKUP(CONCATENATE("Sim",D495),$B$2:$D$1000,3,FALSE())),"") | H503: =IFERROR((VLOOKUP(G503,'Planilha de Cadastro - Previsão'!$A$2:$N$1100,2,FALSE()))," ") | I503: =IFERROR((VLOOKUP(G503,'Planilha de Cadastro - Previsão'!$A$2:$N$1100,3,FALSE()))," ") | J503: =IFERROR((VLOOKUP(G503,'Planilha de Cadastro - Previsão'!$A$2:$N$1100,5,FALSE()))," ") | K503: =IFERROR((VLOOKUP(G503,'Planilha de Cadastro - Previsão'!$A$2:$N$1100,9,FALSE()))," ")
A504: =COUNTIF($C$2:C504,C504) -> 503 | B504: =IFERROR(CONCATENATE(C504,A504),"") -> 503 | C504: =IFERROR(VLOOKUP(D504,'Planilha de Cadastro - Previsão'!$A$2:$O$1000,15,FALSE()),"") | D504: 503
A505: =COUNTIF($C$2:C505,C505) -> 504 | B505: =IFERROR(CONCATENATE(C505,A505),"") -> 504 | C505: =IFERROR(VLOOKUP(D505,'Planilha de Cadastro - Previsão'!$A$2:$O$1000,15,FALSE()),"") | D505: 504
A506: =COUNTIF($C$2:C506,C506) -> 505 | B506: =IFERROR(CONCATENATE(C506,A506),"") -> 505 | C506: =IFERROR(VLOOKUP(D506,'Planilha de Cadastro - Previsão'!$A$2:$O$1000,15,FALSE()),"") | D506: 505 | H506: Total da Proposta | J506: =SUMPRODUCT('Prosposta Inicial'!$I$10:$I$503,'Prosposta Inicial'!$J$10:$J$503) -> 0
A507: =COUNTIF($C$2:C507,C507) -> 506 | B507: =IFERROR(CONCATENATE(C507,A507),"") -> 506 | C507: =IFERROR(VLOOKUP(D507,'Planilha de Cadastro - Previsão'!$A$2:$O$1000,15,FALSE()),"") | D507: 506
A508: =COUNTIF($C$2:C508,C508) -> 507 | B508: =IFERROR(CONCATENATE(C508,A508),"") -> 507 | C508: =IFERROR(VLOOKUP(D508,'Planilha de Cadastro - Previsão'!$A$2:$O$1000,15,FALSE()),"") | D508: 507
A509: =COUNTIF($C$2:C509,C509) -> 508 | B509: =IFERROR(CONCATENATE(C509,A509),"") -> 508 | C509: =IFERROR(VLOOKUP(D509,'Planilha de Cadastro - Previsão'!$A$2:$O$1000,15,FALSE()),"") | D509: 508
A510: =COUNTIF($C$2:C510,C510) -> 509 | B510: =IFERROR(CONCATENATE(C510,A510),"") -> 509 | C510: =IFERROR(VLOOKUP(D510,'Planilha de Cadastro - Previsão'!$A$2:$O$1000,15,FALSE()),"") | D510: 509
...

Sheet Acompanhamento da Licitação
A1: Repetições | B1: Junção | C1: Preço Preenchido | D1: Ordem dos Lotes | F1: Lote | G1: Item | H1: Quantidade | I1: Valor da Compra | J1: Valor da Venda Prevista | K1: Valor da Venda Real | L1: Lucro Real | M1: % de Lucro | N1: Vencedor | O1: Responsável pelos Lances | R1: Alef Freire
A2: =COUNTIF($C$2:C2,C2) -> 1 | B2: =IFERROR(CONCATENATE(C2,A2),"") -> 1 | C2: =IFERROR(VLOOKUP(D2,'Planilha de Cadastro - Previsão'!$A$2:$O$1000,15,FALSE()),"") | D2: 1 | F2: =IFERROR((VLOOKUP(CONCATENATE("Sim",D2),$B$2:$D$1000,3,FALSE())),"") | G2: =IFERROR((VLOOKUP(F2,'Planilha de Cadastro - Previsão'!$A$2:$N$1100,2,FALSE()))," ") | H2: =IFERROR((VLOOKUP(F2,'Planilha de Cadastro - Previsão'!$A$2:$N$1100,3,FALSE()))," ") | I2: =IFERROR((VLOOKUP(F2,'Planilha de Cadastro - Previsão'!$A$2:$N$1100,4,FALSE()))," ") | J2: =IFERROR((VLOOKUP(F2,'Planilha de Cadastro - Previsão'!$A$2:$N$1100,5,FALSE()))," ") | L2: =IF(K2>0,(K2*H2)-(I2*H2)-(K2*H2*4%),"") | M2: =IFERROR(L2/(K2*H2),"") | R2: Ariane Vieira
A3: =COUNTIF($C$2:C3,C3) -> 2 | B3: =IFERROR(CONCATENATE(C3,A3),"") -> 2 | C3: =IFERROR(VLOOKUP(D3,'Planilha de Cadastro - Previsão'!$A$2:$O$1000,15,FALSE()),"") | D3: 2 | F3: =IFERROR((VLOOKUP(CONCATENATE("Sim",D3),$B$2:$D$1000,3,FALSE())),"") | G3: =IFERROR((VLOOKUP(F3,'Planilha de Cadastro - Previsão'!$A$2:$N$1100,2,FALSE()))," ") | H3: =IFERROR((VLOOKUP(F3,'Planilha de Cadastro - Previsão'!$A$2:$N$1100,3,FALSE()))," ") | I3: =IFERROR((VLOOKUP(F3,'Planilha de Cadastro - Previsão'!$A$2:$N$1100,4,FALSE()))," ") | J3: =IFERROR((VLOOKUP(F3,'Planilha de Cadastro - Previsão'!$A$2:$N$1100,5,FALSE()))," ") | L3: =IF(K3>0,(K3*H3)-(I3*H3)-(K3*H3*4%),"") | M3: =IFERROR(L3/(K3*H3),"") | R3: Barbara Jordão
A4: =COUNTIF($C$2:C4,C4) -> 3 | B4: =IFERROR(CONCATENATE(C4,A4),"") -> 3 | C4: =IFERROR(VLOOKUP(D4,'Planilha de Cadastro - Previsão'!$A$2:$O$1000,15,FALSE()),"") | D4: 3 | F4: =IFERROR((VLOOKUP(CONCATENATE("Sim",D4),$B$2:$D$1000,3,FALSE())),"") | G4: =IFERROR((VLOOKUP(F4,'Planilha de Cadastro - Previsão'!$A$2:$N$1100,2,FALSE()))," ") | H4: =IFERROR((VLOOKUP(F4,'Planilha de Cadastro - Previsão'!$A$2:$N$1100,3,FALSE()))," ") | I4: =IFERROR((VLOOKUP(F4,'Planilha de Cadastro - Previsão'!$A$2:$N$1100,4,FALSE()))," ") | J4: =IFERROR((VLOOKUP(F4,'Planilha de Cadastro - Previsão'!$A$2:$N$1100,5,FALSE()))," ") | L4: =IF(K4>0,(K4*H4)-(I4*H4)-(K4*H4*4%),"") | M4: =IFERROR(L4/(K4*H4),"") | R4: Equipe Mabus
A5: =COUNTIF($C$2:C5,C5) -> 4 | B5: =IFERROR(CONCATENATE(C5,A5),"") -> 4 | C5: =IFERROR(VLOOKUP(D5,'Planilha de Cadastro - Previsão'!$A$2:$O$1000,15,FALSE()),"") | D5: 4 | F5: =IFERROR((VLOOKUP(CONCATENATE("Sim",D5),$B$2:$D$1000,3,FALSE())),"") | G5: =IFERROR((VLOOKUP(F5,'Planilha de Cadastro - Previsão'!$A$2:$N$1100,2,FALSE()))," ") | H5: =IFERROR((VLOOKUP(F5,'Planilha de Cadastro - Previsão'!$A$2:$N$1100,3,FALSE()))," ") | I5: =IFERROR((VLOOKUP(F5,'Planilha de Cadastro - Previsão'!$A$2:$N$1100,4,FALSE()))," ") | J5: =IFERROR((VLOOKUP(F5,'Planilha de Cadastro - Previsão'!$A$2:$N$1100,5,FALSE()))," ") | L5: =IF(K5>0,(K5*H5)-(I5*H5)-(K5*H5*4%),"") | M5: =IFERROR(L5/(K5*H5),"") | R5: Geovanna Candido
A6: =COUNTIF($C$2:C6,C6) -> 5 | B6: =IFERROR(CONCATENATE(C6,A6),"") -> 5 | C6: =IFERROR(VLOOKUP(D6,'Planilha de Cadastro - Previsão'!$A$2:$O$1000,15,FALSE()),"") | D6: 5 | F6: =IFERROR((VLOOKUP(CONCATENATE("Sim",D6),$B$2:$D$1000,3,FALSE())),"") | G6: =IFERROR((VLOOKUP(F6,'Planilha de Cadastro - Previsão'!$A$2:$N$1100,2,FALSE()))," ") | H6: =IFERROR((VLOOKUP(F6,'Planilha de Cadastro - Previsão'!$A$2:$N$1100,3,FALSE()))," ") | I6: =IFERROR((VLOOKUP(F6,'Planilha de Cadastro - Previsão'!$A$2:$N$1100,4,FALSE()))," ") | J6: =IFERROR((VLOOKUP(F6,'Planilha de Cadastro - Previsão'!$A$2:$N$1100,5,FALSE()))," ") | L6: =IF(K6>0,(K6*H6)-(I6*H6)-(K6*H6*4%),"") | M6: =IFERROR(L6/(K6*H6),"") | R6: Guilherme Cândido
A7: =COUNTIF($C$2:C7,C7) -> 6 | B7: =IFERROR(CONCATENATE(C7,A7),"") -> 6 | C7: =IFERROR(VLOOKUP(D7,'Planilha de Cadastro - Previsão'!$A$2:$O$1000,15,FALSE()),"") | D7: 6 | F7: =IFERROR((VLOOKUP(CONCATENATE("Sim",D7),$B$2:$D$1000,3,FALSE())),"") | G7: =IFERROR((VLOOKUP(F7,'Planilha de Cadastro - Previsão'!$A$2:$N$1100,2,FALSE()))," ") | H7: =IFERROR((VLOOKUP(F7,'Planilha de Cadastro - Previsão'!$A$2:$N$1100,3,FALSE()))," ") | I7: =IFERROR((VLOOKUP(F7,'Planilha de Cadastro - Previsão'!$A$2:$N$1100,4,FALSE()))," ") | J7: =IFERROR((VLOOKUP(F7,'Planilha de Cadastro - Previsão'!$A$2:$N$1100,5,FALSE()))," ") | L7: =IF(K7>0,(K7*H7)-(I7*H7)-(K7*H7*4%),"") | M7: =IFERROR(L7/(K7*H7),"") | R7: Heverton Moreira
A8: =COUNTIF($C$2:C8,C8) -> 7 | B8: =IFERROR(CONCATENATE(C8,A8),"") -> 7 | C8: =IFERROR(VLOOKUP(D8,'Planilha de Cadastro - Previsão'!$A$2:$O$1000,15,FALSE()),"") | D8: 7 | F8: =IFERROR((VLOOKUP(CONCATENATE("Sim",D8),$B$2:$D$1000,3,FALSE())),"") | G8: =IFERROR((VLOOKUP(F8,'Planilha de Cadastro - Previsão'!$A$2:$N$1100,2,FALSE()))," ") | H8: =IFERROR((VLOOKUP(F8,'Planilha de Cadastro - Previsão'!$A$2:$N$1100,3,FALSE()))," ") | I8: =IFERROR((VLOOKUP(F8,'Planilha de Cadastro - Previsão'!$A$2:$N$1100,4,FALSE()))," ") | J8: =IFERROR((VLOOKUP(F8,'Planilha de Cadastro - Previsão'!$A$2:$N$1100,5,FALSE()))," ") | L8: =IF(K8>0,(K8*H8)-(I8*H8)-(K8*H8*4%),"") | M8: =IFERROR(L8/(K8*H8),"") | R8: Isabela Gontijo
A9: =COUNTIF($C$2:C9,C9) -> 8 | B9: =IFERROR(CONCATENATE(C9,A9),"") -> 8 | C9: =IFERROR(VLOOKUP(D9,'Planilha de Cadastro - Previsão'!$A$2:$O$1000,15,FALSE()),"") | D9: 8 | F9: =IFERROR((VLOOKUP(CONCATENATE("Sim",D9),$B$2:$D$1000,3,FALSE())),"") | G9: =IFERROR((VLOOKUP(F9,'Planilha de Cadastro - Previsão'!$A$2:$N$1100,2,FALSE()))," ") | H9: =IFERROR((VLOOKUP(F9,'Planilha de Cadastro - Previsão'!$A$2:$N$1100,3,FALSE()))," ") | I9: =IFERROR((VLOOKUP(F9,'Planilha de Cadastro - Previsão'!$A$2:$N$1100,4,FALSE()))," ") | J9: =IFERROR((VLOOKUP(F9,'Planilha de Cadastro - Previsão'!$A$2:$N$1100,5,FALSE()))," ") | L9: =IF(K9>0,(K9*H9)-(I9*H9)-(K9*H9*4%),"") | M9: =IFERROR(L9/(K9*H9),"") | R9: João Vitor Ferreira
A10: =COUNTIF($C$2:C10,C10) -> 9 | B10: =IFERROR(CONCATENATE(C10,A10),"") -> 9 | C10: =IFERROR(VLOOKUP(D10,'Planilha de Cadastro - Previsão'!$A$2:$O$1000,15,FALSE()),"") | D10: 9 | F10: =IFERROR((VLOOKUP(CONCATENATE("Sim",D10),$B$2:$D$1000,3,FALSE())),"") | G10: =IFERROR((VLOOKUP(F10,'Planilha de Cadastro - Previsão'!$A$2:$N$1100,2,FALSE()))," ") | H10: =IFERROR((VLOOKUP(F10,'Planilha de Cadastro - Previsão'!$A$2:$N$1100,3,FALSE()))," ") | I10: =IFERROR((VLOOKUP(F10,'Planilha de Cadastro - Previsão'!$A$2:$N$1100,4,FALSE()))," ") | J10: =IFERROR((VLOOKUP(F10,'Planilha de Cadastro - Previsão'!$A$2:$N$1100,5,FALSE()))," ") | L10: =IF(K10>0,(K10*H10)-(I10*H10)-(K10*H10*4%),"") | M10: =IFERROR(L10/(K10*H10),"") | R10: Leonardo Savan
A11: =COUNTIF($C$2:C11,C11) -> 10 | B11: =IFERROR(CONCATENATE(C11,A11),"") -> 10 | C11: =IFERROR(VLOOKUP(D11,'Planilha de Cadastro - Previsão'!$A$2:$O$1000,15,FALSE()),"") | D11: 10 | F11: =IFERROR((VLOOKUP(CONCATENATE("Sim",D11),$B$2:$D$1000,3,FALSE())),"") | G11: =IFERROR((VLOOKUP(F11,'Planilha de Cadastro - Previsão'!$A$2:$N$1100,2,FALSE()))," ") | H11: =IFERROR((VLOOKUP(F11,'Planilha de Cadastro - Previsão'!$A$2:$N$1100,3,FALSE()))," ") | I11: =IFERROR((VLOOKUP(F11,'Planilha de Cadastro - Previsão'!$A$2:$N$1100,4,FALSE()))," ") | J11: =IFERROR((VLOOKUP(F11,'Planilha de Cadastro - Previsão'!$A$2:$N$1100,5,FALSE()))," ") | L11: =IF(K11>0,(K11*H11)-(I11*H11)-(K11*H11*4%),"") | M11: =IFERROR(L11/(K11*H11),"") | R11: Livia Andrade
A12: =COUNTIF($C$2:C12,C12) -> 11 | B12: =IFERROR(CONCATENATE(C12,A12),"") -> 11 | C12: =IFERROR(VLOOKUP(D12,'Planilha de Cadastro - Previsão'!$A$2:$O$1000,15,FALSE()),"") | D12: 11 | F12: =IFERROR((VLOOKUP(CONCATENATE("Sim",D12),$B$2:$D$1000,3,FALSE())),"") | G12: =IFERROR((VLOOKUP(F12,'Planilha de Cadastro - Previsão'!$A$2:$N$1100,2,FALSE()))," ") | H12: =IFERROR((VLOOKUP(F12,'Planilha de Cadastro - Previsão'!$A$2:$N$1100,3,FALSE()))," ") | I12: =IFERROR((VLOOKUP(F12,'Planilha de Cadastro - Previsão'!$A$2:$N$1100,4,FALSE()))," ") | J12: =IFERROR((VLOOKUP(F12,'Planilha de Cadastro - Previsão'!$A$2:$N$1100,5,FALSE()))," ") | L12: =IF(K12>0,(K12*H12)-(I12*H12)-(K12*H12*4%),"") | M12: =IFERROR(L12/(K12*H12),"") | R12: Nathalia Barroti
A13: =COUNTIF($C$2:C13,C13) -> 12 | B13: =IFERROR(CONCATENATE(C13,A13),"") -> 12 | C13: =IFERROR(VLOOKUP(D13,'Planilha de Cadastro - Previsão'!$A$2:$O$1000,15,FALSE()),"") | D13: 12 | F13: =IFERROR((VLOOKUP(CONCATENATE("Sim",D13),$B$2:$D$1000,3,FALSE())),"") | G13: =IFERROR((VLOOKUP(F13,'Planilha de Cadastro - Previsão'!$A$2:$N$1100,2,FALSE()))," ") | H13: =IFERROR((VLOOKUP(F13,'Planilha de Cadastro - Previsão'!$A$2:$N$1100,3,FALSE()))," ") | I13: =IFERROR((VLOOKUP(F13,'Planilha de Cadastro - Previsão'!$A$2:$N$1100,4,FALSE()))," ") | J13: =IFERROR((VLOOKUP(F13,'Planilha de Cadastro - Previsão'!$A$2:$N$1100,5,FALSE()))," ") | L13: =IF(K13>0,(K13*H13)-(I13*H13)-(K13*H13*4%),"") | M13: =IFERROR(L13/(K13*H13),"") | R13: Neto Frederico
... A15: =COUNTIF($C$2:C15,C15) -> 14 | B15: =IFERROR(CONCATENATE(C15,A15),"") -> 14 | C15: =IFERROR(VLOOKUP(D15,'Planilha de Cadastro - Previsão'!$A$2:$O$1000,15,FALSE()),"") | D15: 14 | F15: =IFERROR((VLOOKUP(CONCATENATE("Sim",D15),$B$2:$D$1000,3,FALSE())),"") | G15: =IFERROR((VLOOKUP(F15,'Planilha de Cadastro - Previsão'!$A$2:$N$1100,2,FALSE()))," ") | H15: =IFERROR((VLOOKUP(F15,'Planilha de Cadastro - Previsão'!$A$2:$N$1100,3,FALSE()))," ") | I15: =IFERROR((VLOOKUP(F15,'Planilha de Cadastro - Previsão'!$A$2:$N$1100,4,FALSE()))," ") | J15: =IFERROR((VLOOKUP(F15,'Planilha de Cadastro - Previsão'!$A$2:$N$1100,5,FALSE()))," ") | L15: =IF(K15>0,(K15*H15)-(I15*H15)-(K15*H15*4%),"") | M15: =IFERROR(L15/(K15*H15),"") | R15: Thiago Alves
A16: =COUNTIF($C$2:C16,C16) -> 15 | B16: =IFERROR(CONCATENATE(C16,A16),"") -> 15 | C16: =IFERROR(VLOOKUP(D16,'Planilha de Cadastro - Previsão'!$A$2:$O$1000,15,FALSE()),"") | D16: 15 | F16: =IFERROR((VLOOKUP(CONCATENATE("Sim",D16),$B$2:$D$1000,3,FALSE())),"") | G16: =IFERROR((VLOOKUP(F16,'Planilha de Cadastro - Previsão'!$A$2:$N$1100,2,FALSE()))," ") | H16: =IFERROR((VLOOKUP(F16,'Planilha de Cadastro - Previsão'!$A$2:$N$1100,3,FALSE()))," ") | I16: =IFERROR((VLOOKUP(F16,'Planilha de Cadastro - Previsão'!$A$2:$N$1100,4,FALSE()))," ") | J16: =IFERROR((VLOOKUP(F16,'Planilha de Cadastro - Previsão'!$A$2:$N$1100,5,FALSE()))," ") | L16: =IF(K16>0,(K16*H16)-(I16*H16)-(K16*H16*4%),"") | M16: =IFERROR(L16/(K16*H16),"")
A17: =COUNTIF($C$2:C17,C17) -> 16 | B17: =IFERROR(CONCATENATE(C17,A17),"") -> 16 | C17: =IFERROR(VLOOKUP(D17,'Planilha de Cadastro - Previsão'!$A$2:$O$1000,15,FALSE()),"") | D17: 16 | F17: =IFERROR((VLOOKUP(CONCATENATE("Sim",D17),$B$2:$D$1000,3,FALSE())),"") | G17: =IFERROR((VLOOKUP(F17,'Planilha de Cadastro - Previsão'!$A$2:$N$1100,2,FALSE()))," ") | H17: =IFERROR((VLOOKUP(F17,'Planilha de Cadastro - Previsão'!$A$2:$N$1100,3,FALSE()))," ") | I17: =IFERROR((VLOOKUP(F17,'Planilha de Cadastro - Previsão'!$A$2:$N$1100,4,FALSE()))," ") | J17: =IFERROR((VLOOKUP(F17,'Planilha de Cadastro - Previsão'!$A$2:$N$1100,5,FALSE()))," ") | L17: =IF(K17>0,(K17*H17)-(I17*H17)-(K17*H17*4%),"") | M17: =IFERROR(L17/(K17*H17),"")
A18: =COUNTIF($C$2:C18,C18) -> 17 | B18: =IFERROR(CONCATENATE(C18,A18),"") -> 17 | C18: =IFERROR(VLOOKUP(D18,'Planilha de Cadastro - Previsão'!$A$2:$O$1000,15,FALSE()),"") | D18: 17 | F18: =IFERROR((VLOOKUP(CONCATENATE("Sim",D18),$B$2:$D$1000,3,FALSE())),"") | G18: =IFERROR((VLOOKUP(F18,'Planilha de Cadastro - Previsão'!$A$2:$N$1100,2,FALSE()))," ") | H18: =IFERROR((VLOOKUP(F18,'Planilha de Cadastro - Previsão'!$A$2:$N$1100,3,FALSE()))," ") | I18: =IFERROR((VLOOKUP(F18,'Planilha de Cadastro - Previsão'!$A$2:$N$1100,4,FALSE()))," ") | J18: =IFERROR((VLOOKUP(F18,'Planilha de Cadastro - Previsão'!$A$2:$N$1100,5,FALSE()))," ") | L18: =IF(K18>0,(K18*H18)-(I18*H18)-(K18*H18*4%),"") | M18: =IFERROR(L18/(K18*H18),"")
A19: =COUNTIF($C$2:C19,C19) -> 18 | B19: =IFERROR(CONCATENATE(C19,A19),"") -> 18 | C19: =IFERROR(VLOOKUP(D19,'Planilha de Cadastro - Previsão'!$A$2:$O$1000,15,FALSE()),"") | D19: 18 | F19: =IFERROR((VLOOKUP(CONCATENATE("Sim",D19),$B$2:$D$1000,3,FALSE())),"") | G19: =IFERROR((VLOOKUP(F19,'Planilha de Cadastro - Previsão'!$A$2:$N$1100,2,FALSE()))," ") | H19: =IFERROR((VLOOKUP(F19,'Planilha de Cadastro - Previsão'!$A$2:$N$1100,3,FALSE()))," ") | I19: =IFERROR((VLOOKUP(F19,'Planilha de Cadastro - Previsão'!$A$2:$N$1100,4,FALSE()))," ") | J19: =IFERROR((VLOOKUP(F19,'Planilha de Cadastro - Previsão'!$A$2:$N$1100,5,FALSE()))," ") | L19: =IF(K19>0,(K19*H19)-(I19*H19)-(K19*H19*4%),"") | M19: =IFERROR(L19/(K19*H19),"")
A20: =COUNTIF($C$2:C20,C20) -> 19 | B20: =IFERROR(CONCATENATE(C20,A20),"") -> 19 | C20: =IFERROR(VLOOKUP(D20,'Planilha de Cadastro - Previsão'!$A$2:$O$1000,15,FALSE()),"") | D20: 19 | F20: =IFERROR((VLOOKUP(CONCATENATE("Sim",D20),$B$2:$D$1000,3,FALSE())),"") | G20: =IFERROR((VLOOKUP(F20,'Planilha de Cadastro - Previsão'!$A$2:$N$1100,2,FALSE()))," ") | H20: =IFERROR((VLOOKUP(F20,'Planilha de Cadastro - Previsão'!$A$2:$N$1100,3,FALSE()))," ") | I20: =IFERROR((VLOOKUP(F20,'Planilha de Cadastro - Previsão'!$A$2:$N$1100,4,FALSE()))," ") | J20: =IFERROR((VLOOKUP(F20,'Planilha de Cadastro - Previsão'!$A$2:$N$1100,5,FALSE()))," ") | L20: =IF(K20>0,(K20*H20)-(I20*H20)-(K20*H20*4%),"") | M20: =IFERROR(L20/(K20*H20),"")
A21: =COUNTIF($C$2:C21,C21) -> 20 | B21: =IFERROR(CONCATENATE(C21,A21),"") -> 20 | C21: =IFERROR(VLOOKUP(D21,'Planilha de Cadastro - Previsão'!$A$2:$O$1000,15,FALSE()),"") | D21: 20 | F21: =IFERROR((VLOOKUP(CONCATENATE("Sim",D21),$B$2:$D$1000,3,FALSE())),"") | G21: =IFERROR((VLOOKUP(F21,'Planilha de Cadastro - Previsão'!$A$2:$N$1100,2,FALSE()))," ") | H21: =IFERROR((VLOOKUP(F21,'Planilha de Cadastro - Previsão'!$A$2:$N$1100,3,FALSE()))," ") | I21: =IFERROR((VLOOKUP(F21,'Planilha de Cadastro - Previsão'!$A$2:$N$1100,4,FALSE()))," ") | J21: =IFERROR((VLOOKUP(F21,'Planilha de Cadastro - Previsão'!$A$2:$N$1100,5,FALSE()))," ") | L21: =IF(K21>0,(K21*H21)-(I21*H21)-(K21*H21*4%),"") | M21: =IFERROR(L21/(K21*H21),"")
A22: =COUNTIF($C$2:C22,C22) -> 21 | B22: =IFERROR(CONCATENATE(C22,A22),"") -> 21 | C22: =IFERROR(VLOOKUP(D22,'Planilha de Cadastro - Previsão'!$A$2:$O$1000,15,FALSE()),"") | D22: 21 | F22: =IFERROR((VLOOKUP(CONCATENATE("Sim",D22),$B$2:$D$1000,3,FALSE())),"") | G22: =IFERROR((VLOOKUP(F22,'Planilha de Cadastro - Previsão'!$A$2:$N$1100,2,FALSE()))," ") | H22: =IFERROR((VLOOKUP(F22,'Planilha de Cadastro - Previsão'!$A$2:$N$1100,3,FALSE()))," ") | I22: =IFERROR((VLOOKUP(F22,'Planilha de Cadastro - Previsão'!$A$2:$N$1100,4,FALSE()))," ") | J22: =IFERROR((VLOOKUP(F22,'Planilha de Cadastro - Previsão'!$A$2:$N$1100,5,FALSE()))," ") | L22: =IF(K22>0,(K22*H22)-(I22*H22)-(K22*H22*4%),"") | M22: =IFERROR(L22/(K22*H22),"")
A23: =COUNTIF($C$2:C23,C23) -> 22 | B23: =IFERROR(CONCATENATE(C23,A23),"") -> 22 | C23: =IFERROR(VLOOKUP(D23,'Planilha de Cadastro - Previsão'!$A$2:$O$1000,15,FALSE()),"") | D23: 22 | F23: =IFERROR((VLOOKUP(CONCATENATE("Sim",D23),$B$2:$D$1000,3,FALSE())),"") | G23: =IFERROR((VLOOKUP(F23,'Planilha de Cadastro - Previsão'!$A$2:$N$1100,2,FALSE()))," ") | H23: =IFERROR((VLOOKUP(F23,'Planilha de Cadastro - Previsão'!$A$2:$N$1100,3,FALSE()))," ") | I23: =IFERROR((VLOOKUP(F23,'Planilha de Cadastro - Previsão'!$A$2:$N$1100,4,FALSE()))," ") | J23: =IFERROR((VLOOKUP(F23,'Planilha de Cadastro - Previsão'!$A$2:$N$1100,5,FALSE()))," ") | L23: =IF(K23>0,(K23*H23)-(I23*H23)-(K23*H23*4%),"") | M23: =IFERROR(L23/(K23*H23),"")
A24: =COUNTIF($C$2:C24,C24) -> 23 | B24: =IFERROR(CONCATENATE(C24,A24),"") -> 23 | C24: =IFERROR(VLOOKUP(D24,'Planilha de Cadastro - Previsão'!$A$2:$O$1000,15,FALSE()),"") | D24: 23 | F24: =IFERROR((VLOOKUP(CONCATENATE("Sim",D24),$B$2:$D$1000,3,FALSE())),"") | G24: =IFERROR((VLOOKUP(F24,'Planilha de Cadastro - Previsão'!$A$2:$N$1100,2,FALSE()))," ") | H24: =IFERROR((VLOOKUP(F24,'Planilha de Cadastro - Previsão'!$A$2:$N$1100,3,FALSE()))," ") | I24: =IFERROR((VLOOKUP(F24,'Planilha de Cadastro - Previsão'!$A$2:$N$1100,4,FALSE()))," ") | J24: =IFERROR((VLOOKUP(F24,'Planilha de Cadastro - Previsão'!$A$2:$N$1100,5,FALSE()))," ") | L24: =IF(K24>0,(K24*H24)-(I24*H24)-(K24*H24*4%),"") | M24: =IFERROR(L24/(K24*H24),"")
A25: =COUNTIF($C$2:C25,C25) -> 24 | B25: =IFERROR(CONCATENATE(C25,A25),"") -> 24 | C25: =IFERROR(VLOOKUP(D25,'Planilha de Cadastro - Previsão'!$A$2:$O$1000,15,FALSE()),"") | D25: 24 | F25: =IFERROR((VLOOKUP(CONCATENATE("Sim",D25),$B$2:$D$1000,3,FALSE())),"") | G25: =IFERROR((VLOOKUP(F25,'Planilha de Cadastro - Previsão'!$A$2:$N$1100,2,FALSE()))," ") | H25: =IFERROR((VLOOKUP(F25,'Planilha de Cadastro - Previsão'!$A$2:$N$1100,3,FALSE()))," ") | I25: =IFERROR((VLOOKUP(F25,'Planilha de Cadastro - Previsão'!$A$2:$N$1100,4,FALSE()))," ") | J25: =IFERROR((VLOOKUP(F25,'Planilha de Cadastro - Previsão'!$A$2:$N$1100,5,FALSE()))," ") | L25: =IF(K25>0,(K25*H25)-(I25*H25)-(K25*H25*4%),"") | M25: =IFERROR(L25/(K25*H25),"")
A26: =COUNTIF($C$2:C26,C26) -> 25 | B26: =IFERROR(CONCATENATE(C26,A26),"") -> 25 | C26: =IFERROR(VLOOKUP(D26,'Planilha de Cadastro - Previsão'!$A$2:$O$1000,15,FALSE()),"") | D26: 25 | F26: =IFERROR((VLOOKUP(CONCATENATE("Sim",D26),$B$2:$D$1000,3,FALSE())),"") | G26: =IFERROR((VLOOKUP(F26,'Planilha de Cadastro - Previsão'!$A$2:$N$1100,2,FALSE()))," ") | H26: =IFERROR((VLOOKUP(F26,'Planilha de Cadastro - Previsão'!$A$2:$N$1100,3,FALSE()))," ") | I26: =IFERROR((VLOOKUP(F26,'Planilha de Cadastro - Previsão'!$A$2:$N$1100,4,FALSE()))," ") | J26: =IFERROR((VLOOKUP(F26,'Planilha de Cadastro - Previsão'!$A$2:$N$1100,5,FALSE()))," ") | L26: =IF(K26>0,(K26*H26)-(I26*H26)-(K26*H26*4%),"") | M26: =IFERROR(L26/(K26*H26),"")
A27: =COUNTIF($C$2:C27,C27) -> 26 | B27: =IFERROR(CONCATENATE(C27,A27),"") -> 26 | C27: =IFERROR(VLOOKUP(D27,'Planilha de Cadastro - Previsão'!$A$2:$O$1000,15,FALSE()),"") | D27: 26 | F27: =IFERROR((VLOOKUP(CONCATENATE("Sim",D27),$B$2:$D$1000,3,FALSE())),"") | G27: =IFERROR((VLOOKUP(F27,'Planilha de Cadastro - Previsão'!$A$2:$N$1100,2,FALSE()))," ") | H27: =IFERROR((VLOOKUP(F27,'Planilha de Cadastro - Previsão'!$A$2:$N$1100,3,FALSE()))," ") | I27: =IFERROR((VLOOKUP(F27,'Planilha de Cadastro - Previsão'!$A$2:$N$1100,4,FALSE()))," ") | J27: =IFERROR((VLOOKUP(F27,'Planilha de Cadastro - Previsão'!$A$2:$N$1100,5,FALSE()))," ") | L27: =IF(K27>0,(K27*H27)-(I27*H27)-(K27*H27*4%),"") | M27: =IFERROR(L27/(K27*H27),"")
... A1000: =COUNTIF($C$2:C1000,C1000) -> 999 | B1000: =IFERROR(CONCATENATE(C1000,A1000),"") -> 999 | C1000: =IFERROR(VLOOKUP(D1000,'Planilha de Cadastro - Previsão'!$A$2:$O$1000,15,FALSE()),"") | D1000: 999 | F1000: =IFERROR((VLOOKUP(CONCATENATE("Sim",D1000),$B$2:$D$1000,3,FALSE())),"") | G1000: =IFERROR((VLOOKUP(F1000,'Planilha de Cadastro - Previsão'!$A$2:$N$1100,2,FALSE()))," ") | H1000: =IFERROR((VLOOKUP(F1000,'Planilha de Cadastro - Previsão'!$A$2:$N$1100,3,FALSE()))," ") | I1000: =IFERROR((VLOOKUP(F1000,'Planilha de Cadastro - Previsão'!$A$2:$N$1100,4,FALSE()))," ") | J1000: =IFERROR((VLOOKUP(F1000,'Planilha de Cadastro - Previsão'!$A$2:$N$1100,5,FALSE()))," ") | L1000: =IF(K1000>0,(K1000*H1000)-(I1000*H1000)-(K1000*H1000*4%),"") | M1000: =IFERROR(L1000/(K1000*H1000),"")

Sheet Itens Vencedores
A1: Repetições | B1: Junção | C1: Vencedor | D1: Ordem dos Lotes | F1: Lote | G1: Município | H1: Concatenar | I1: Item | J1: Quantidade | K1: Valor de Compra Previsto | L1: Valor da Venda Real | M1: Link da Compra | N1: Marca | O1: Responsável Pela Cotação | P1: Responsável pelos Lances | R1: % de Lucro Previsto | S1: % Comissão Prevista | T1: R$ Comissão Prevista
